{
  "cells": [
    {
      "cell_type": "markdown",
      "metadata": {
        "id": "view-in-github",
        "colab_type": "text"
      },
      "source": [
        "<a href=\"https://colab.research.google.com/github/harshikagoyal14/Articles-ChatBot/blob/main/Untitled19.ipynb\" target=\"_parent\"><img src=\"https://colab.research.google.com/assets/colab-badge.svg\" alt=\"Open In Colab\"/></a>"
      ]
    },
    {
      "cell_type": "code",
      "execution_count": null,
      "metadata": {
        "id": "6-irQWkmIfvW"
      },
      "outputs": [],
      "source": [
        "!pip install langchain==0.0.284\n",
        "!pip install python-dotenv==1.0.0\n",
        "!pip install streamlit==1.22.0\n",
        "!pip install unstructured==0.9.2\n",
        "!pip install tiktoken==0.4.0\n",
        "!pip install faiss-cpu==1.7.4\n",
        "!pip install libmagic==1.0\n",
        "!pip install python-magic==0.4.27\n",
        "!pip install python-magic-bin==0.4.14\n",
        "!pip install openai==0.28.0\n"
      ]
    },
    {
      "cell_type": "code",
      "execution_count": 2,
      "metadata": {
        "id": "TFfb7zqaI5b6"
      },
      "outputs": [],
      "source": [
        "import os\n",
        "import streamlit as st\n",
        "import pickle\n",
        "import time\n",
        "from langchain import OpenAI\n",
        "from langchain.chains import RetrievalQAWithSourcesChain\n",
        "from langchain.text_splitter import RecursiveCharacterTextSplitter\n",
        "from langchain.document_loaders import UnstructuredURLLoader\n",
        "from langchain.embeddings import OpenAIEmbeddings\n",
        "from langchain.vectorstores import FAISS"
      ]
    },
    {
      "cell_type": "code",
      "source": [
        "%%writefile app.py"
      ],
      "metadata": {
        "colab": {
          "base_uri": "https://localhost:8080/"
        },
        "id": "FULSgr4sx9_9",
        "outputId": "53e346b9-adec-4e05-fc05-bc6a8442189a"
      },
      "execution_count": 3,
      "outputs": [
        {
          "output_type": "stream",
          "name": "stdout",
          "text": [
            "Writing app.py\n"
          ]
        }
      ]
    },
    {
      "cell_type": "code",
      "source": [
        "! wget -q -O - ipv4.icanhazip.com"
      ],
      "metadata": {
        "colab": {
          "base_uri": "https://localhost:8080/"
        },
        "id": "GNMJOabuyINm",
        "outputId": "43b2c0dc-4cd5-4449-a05a-391ab3573d84"
      },
      "execution_count": 4,
      "outputs": [
        {
          "output_type": "stream",
          "name": "stdout",
          "text": [
            "34.106.169.192\n"
          ]
        }
      ]
    },
    {
      "cell_type": "code",
      "source": [
        "! streamlit run app.py & npx localtunnel --port 8501"
      ],
      "metadata": {
        "colab": {
          "base_uri": "https://localhost:8080/"
        },
        "id": "Q4I8I0wuyaZ7",
        "outputId": "cf255c8c-2abf-4d77-97f3-9db1006ee150"
      },
      "execution_count": null,
      "outputs": [
        {
          "output_type": "stream",
          "name": "stdout",
          "text": [
            "[..................] / fetchMetadata: sill resolveWithNewModule localtunnel@2.0\u001b[0m\u001b[K\n",
            "Collecting usage statistics. To deactivate, set browser.gatherUsageStats to False.\n",
            "\u001b[0m\n",
            "\u001b[0m\n",
            "\u001b[34m\u001b[1m  You can now view your Streamlit app in your browser.\u001b[0m\n",
            "\u001b[0m\n",
            "\u001b[34m  Network URL: \u001b[0m\u001b[1mhttp://172.28.0.12:8501\u001b[0m\n",
            "\u001b[34m  External URL: \u001b[0m\u001b[1mhttp://34.106.169.192:8501\u001b[0m\n",
            "\u001b[0m\n",
            "\u001b[K\u001b[?25hnpx: installed 22 in 3.943s\n",
            "your url is: https://swift-bugs-repeat.loca.lt\n",
            "2024-05-06 07:31:34.470 Uncaught app exception\n",
            "Traceback (most recent call last):\n",
            "  File \"/usr/local/lib/python3.10/dist-packages/streamlit/runtime/scriptrunner/script_runner.py\", line 565, in _run_script\n",
            "    exec(code, module.__dict__)\n",
            "  File \"/content/app.py\", line 28, in <module>\n",
            "    llm = OpenAI(temperature=0.9, max_tokens=500)\n",
            "  File \"/usr/local/lib/python3.10/dist-packages/langchain/load/serializable.py\", line 75, in __init__\n",
            "    super().__init__(**kwargs)\n",
            "  File \"/usr/local/lib/python3.10/dist-packages/pydantic/v1/main.py\", line 341, in __init__\n",
            "    raise validation_error\n",
            "pydantic.v1.error_wrappers.ValidationError: 1 validation error for OpenAI\n",
            "__root__\n",
            "  Did not find openai_api_key, please add an environment variable `OPENAI_API_KEY` which contains it, or pass  `openai_api_key` as a named parameter. (type=value_error)\n",
            "2024-05-06 07:32:35.727 Uncaught app exception\n",
            "Traceback (most recent call last):\n",
            "  File \"/usr/local/lib/python3.10/dist-packages/streamlit/runtime/scriptrunner/script_runner.py\", line 565, in _run_script\n",
            "    exec(code, module.__dict__)\n",
            "  File \"/content/app.py\", line 28, in <module>\n",
            "    llm = OpenAI(temperature=0.9, max_tokens=500)\n",
            "  File \"/usr/local/lib/python3.10/dist-packages/langchain/load/serializable.py\", line 75, in __init__\n",
            "    super().__init__(**kwargs)\n",
            "  File \"/usr/local/lib/python3.10/dist-packages/pydantic/v1/main.py\", line 341, in __init__\n",
            "    raise validation_error\n",
            "pydantic.v1.error_wrappers.ValidationError: 1 validation error for OpenAI\n",
            "__root__\n",
            "  Did not find openai_api_key, please add an environment variable `OPENAI_API_KEY` which contains it, or pass  `openai_api_key` as a named parameter. (type=value_error)\n",
            "2024-05-06 07:33:53.877 Uncaught app exception\n",
            "Traceback (most recent call last):\n",
            "  File \"/usr/local/lib/python3.10/dist-packages/streamlit/runtime/scriptrunner/script_runner.py\", line 565, in _run_script\n",
            "    exec(code, module.__dict__)\n",
            "  File \"/content/app.py\", line 28, in <module>\n",
            "    llm = OpenAI(temperature=0.9, max_tokens=500)\n",
            "  File \"/usr/local/lib/python3.10/dist-packages/langchain/load/serializable.py\", line 75, in __init__\n",
            "    super().__init__(**kwargs)\n",
            "  File \"/usr/local/lib/python3.10/dist-packages/pydantic/v1/main.py\", line 341, in __init__\n",
            "    raise validation_error\n",
            "pydantic.v1.error_wrappers.ValidationError: 1 validation error for OpenAI\n",
            "__root__\n",
            "  Did not find openai_api_key, please add an environment variable `OPENAI_API_KEY` which contains it, or pass  `openai_api_key` as a named parameter. (type=value_error)\n",
            "2024-05-06 07:36:08.499 Uncaught app exception\n",
            "Traceback (most recent call last):\n",
            "  File \"/usr/local/lib/python3.10/dist-packages/streamlit/runtime/scriptrunner/script_runner.py\", line 565, in _run_script\n",
            "    exec(code, module.__dict__)\n",
            "  File \"/content/app.py\", line 28, in <module>\n",
            "    llm = OpenAI(temperature=0.9, max_tokens=500)\n",
            "  File \"/usr/local/lib/python3.10/dist-packages/langchain/load/serializable.py\", line 75, in __init__\n",
            "    super().__init__(**kwargs)\n",
            "  File \"/usr/local/lib/python3.10/dist-packages/pydantic/v1/main.py\", line 341, in __init__\n",
            "    raise validation_error\n",
            "pydantic.v1.error_wrappers.ValidationError: 1 validation error for OpenAI\n",
            "__root__\n",
            "  Did not find openai_api_key, please add an environment variable `OPENAI_API_KEY` which contains it, or pass  `openai_api_key` as a named parameter. (type=value_error)\n",
            "[nltk_data] Downloading package punkt to /root/nltk_data...\n",
            "[nltk_data]   Unzipping tokenizers/punkt.zip.\n",
            "[nltk_data] Downloading package averaged_perceptron_tagger to\n",
            "[nltk_data]     /root/nltk_data...\n",
            "[nltk_data]   Unzipping taggers/averaged_perceptron_tagger.zip.\n",
            "2024-05-06 07:39:30.066 Uncaught app exception\n",
            "Traceback (most recent call last):\n",
            "  File \"/usr/local/lib/python3.10/dist-packages/streamlit/runtime/scriptrunner/script_runner.py\", line 565, in _run_script\n",
            "    exec(code, module.__dict__)\n",
            "  File \"/content/app.py\", line 45, in <module>\n",
            "    embeddings = OpenAIEmbeddings()\n",
            "  File \"/usr/local/lib/python3.10/dist-packages/pydantic/v1/main.py\", line 341, in __init__\n",
            "    raise validation_error\n",
            "pydantic.v1.error_wrappers.ValidationError: 1 validation error for OpenAIEmbeddings\n",
            "__root__\n",
            "  Did not find openai_api_key, please add an environment variable `OPENAI_API_KEY` which contains it, or pass  `openai_api_key` as a named parameter. (type=value_error)\n",
            "Retrying langchain.embeddings.openai.embed_with_retry.<locals>._embed_with_retry in 4.0 seconds as it raised RateLimitError: You exceeded your current quota, please check your plan and billing details. For more information on this error, read the docs: https://platform.openai.com/docs/guides/error-codes/api-errors..\n",
            "Retrying langchain.embeddings.openai.embed_with_retry.<locals>._embed_with_retry in 4.0 seconds as it raised RateLimitError: You exceeded your current quota, please check your plan and billing details. For more information on this error, read the docs: https://platform.openai.com/docs/guides/error-codes/api-errors..\n",
            "Retrying langchain.embeddings.openai.embed_with_retry.<locals>._embed_with_retry in 4.0 seconds as it raised RateLimitError: You exceeded your current quota, please check your plan and billing details. For more information on this error, read the docs: https://platform.openai.com/docs/guides/error-codes/api-errors..\n",
            "Retrying langchain.embeddings.openai.embed_with_retry.<locals>._embed_with_retry in 8.0 seconds as it raised RateLimitError: You exceeded your current quota, please check your plan and billing details. For more information on this error, read the docs: https://platform.openai.com/docs/guides/error-codes/api-errors..\n",
            "Retrying langchain.embeddings.openai.embed_with_retry.<locals>._embed_with_retry in 10.0 seconds as it raised RateLimitError: You exceeded your current quota, please check your plan and billing details. For more information on this error, read the docs: https://platform.openai.com/docs/guides/error-codes/api-errors..\n",
            "2024-05-06 07:41:40.380 Uncaught app exception\n",
            "Traceback (most recent call last):\n",
            "  File \"/usr/local/lib/python3.10/dist-packages/streamlit/runtime/scriptrunner/script_runner.py\", line 565, in _run_script\n",
            "    exec(code, module.__dict__)\n",
            "  File \"/content/app.py\", line 46, in <module>\n",
            "    vectorstore_openai = FAISS.from_documents(docs, embeddings)\n",
            "  File \"/usr/local/lib/python3.10/dist-packages/langchain/vectorstores/base.py\", line 417, in from_documents\n",
            "    return cls.from_texts(texts, embedding, metadatas=metadatas, **kwargs)\n",
            "  File \"/usr/local/lib/python3.10/dist-packages/langchain/vectorstores/faiss.py\", line 602, in from_texts\n",
            "    embeddings = embedding.embed_documents(texts)\n",
            "  File \"/usr/local/lib/python3.10/dist-packages/langchain/embeddings/openai.py\", line 483, in embed_documents\n",
            "    return self._get_len_safe_embeddings(texts, engine=self.deployment)\n",
            "  File \"/usr/local/lib/python3.10/dist-packages/langchain/embeddings/openai.py\", line 367, in _get_len_safe_embeddings\n",
            "    response = embed_with_retry(\n",
            "  File \"/usr/local/lib/python3.10/dist-packages/langchain/embeddings/openai.py\", line 107, in embed_with_retry\n",
            "    return _embed_with_retry(**kwargs)\n",
            "  File \"/usr/local/lib/python3.10/dist-packages/tenacity/__init__.py\", line 289, in wrapped_f\n",
            "    return self(f, *args, **kw)\n",
            "  File \"/usr/local/lib/python3.10/dist-packages/tenacity/__init__.py\", line 379, in __call__\n",
            "    do = self.iter(retry_state=retry_state)\n",
            "  File \"/usr/local/lib/python3.10/dist-packages/tenacity/__init__.py\", line 325, in iter\n",
            "    raise retry_exc.reraise()\n",
            "  File \"/usr/local/lib/python3.10/dist-packages/tenacity/__init__.py\", line 158, in reraise\n",
            "    raise self.last_attempt.result()\n",
            "  File \"/usr/lib/python3.10/concurrent/futures/_base.py\", line 451, in result\n",
            "    return self.__get_result()\n",
            "  File \"/usr/lib/python3.10/concurrent/futures/_base.py\", line 403, in __get_result\n",
            "    raise self._exception\n",
            "  File \"/usr/local/lib/python3.10/dist-packages/tenacity/__init__.py\", line 382, in __call__\n",
            "    result = fn(*args, **kwargs)\n",
            "  File \"/usr/local/lib/python3.10/dist-packages/langchain/embeddings/openai.py\", line 104, in _embed_with_retry\n",
            "    response = embeddings.client.create(**kwargs)\n",
            "  File \"/usr/local/lib/python3.10/dist-packages/openai/api_resources/embedding.py\", line 33, in create\n",
            "    response = super().create(*args, **kwargs)\n",
            "  File \"/usr/local/lib/python3.10/dist-packages/openai/api_resources/abstract/engine_api_resource.py\", line 153, in create\n",
            "    response, _, api_key = requestor.request(\n",
            "  File \"/usr/local/lib/python3.10/dist-packages/openai/api_requestor.py\", line 298, in request\n",
            "    resp, got_stream = self._interpret_response(result, stream)\n",
            "  File \"/usr/local/lib/python3.10/dist-packages/openai/api_requestor.py\", line 700, in _interpret_response\n",
            "    self._interpret_response_line(\n",
            "  File \"/usr/local/lib/python3.10/dist-packages/openai/api_requestor.py\", line 765, in _interpret_response_line\n",
            "    raise self.handle_error_response(\n",
            "openai.error.RateLimitError: You exceeded your current quota, please check your plan and billing details. For more information on this error, read the docs: https://platform.openai.com/docs/guides/error-codes/api-errors.\n",
            "Error fetching or processing , exception: Exactly one of file, filename and url must be specified.\n",
            "Error fetching or processing , exception: Exactly one of file, filename and url must be specified.\n",
            "Retrying langchain.embeddings.openai.embed_with_retry.<locals>._embed_with_retry in 4.0 seconds as it raised RateLimitError: You exceeded your current quota, please check your plan and billing details. For more information on this error, read the docs: https://platform.openai.com/docs/guides/error-codes/api-errors..\n",
            "Retrying langchain.embeddings.openai.embed_with_retry.<locals>._embed_with_retry in 4.0 seconds as it raised RateLimitError: You exceeded your current quota, please check your plan and billing details. For more information on this error, read the docs: https://platform.openai.com/docs/guides/error-codes/api-errors..\n",
            "Retrying langchain.embeddings.openai.embed_with_retry.<locals>._embed_with_retry in 4.0 seconds as it raised RateLimitError: You exceeded your current quota, please check your plan and billing details. For more information on this error, read the docs: https://platform.openai.com/docs/guides/error-codes/api-errors..\n",
            "Retrying langchain.embeddings.openai.embed_with_retry.<locals>._embed_with_retry in 8.0 seconds as it raised RateLimitError: You exceeded your current quota, please check your plan and billing details. For more information on this error, read the docs: https://platform.openai.com/docs/guides/error-codes/api-errors..\n",
            "Retrying langchain.embeddings.openai.embed_with_retry.<locals>._embed_with_retry in 10.0 seconds as it raised RateLimitError: You exceeded your current quota, please check your plan and billing details. For more information on this error, read the docs: https://platform.openai.com/docs/guides/error-codes/api-errors..\n",
            "2024-05-06 07:44:36.819 Uncaught app exception\n",
            "Traceback (most recent call last):\n",
            "  File \"/usr/local/lib/python3.10/dist-packages/streamlit/runtime/scriptrunner/script_runner.py\", line 565, in _run_script\n",
            "    exec(code, module.__dict__)\n",
            "  File \"/content/app.py\", line 46, in <module>\n",
            "    vectorstore_openai = FAISS.from_documents(docs, embeddings)\n",
            "  File \"/usr/local/lib/python3.10/dist-packages/langchain/vectorstores/base.py\", line 417, in from_documents\n",
            "    return cls.from_texts(texts, embedding, metadatas=metadatas, **kwargs)\n",
            "  File \"/usr/local/lib/python3.10/dist-packages/langchain/vectorstores/faiss.py\", line 602, in from_texts\n",
            "    embeddings = embedding.embed_documents(texts)\n",
            "  File \"/usr/local/lib/python3.10/dist-packages/langchain/embeddings/openai.py\", line 483, in embed_documents\n",
            "    return self._get_len_safe_embeddings(texts, engine=self.deployment)\n",
            "  File \"/usr/local/lib/python3.10/dist-packages/langchain/embeddings/openai.py\", line 367, in _get_len_safe_embeddings\n",
            "    response = embed_with_retry(\n",
            "  File \"/usr/local/lib/python3.10/dist-packages/langchain/embeddings/openai.py\", line 107, in embed_with_retry\n",
            "    return _embed_with_retry(**kwargs)\n",
            "  File \"/usr/local/lib/python3.10/dist-packages/tenacity/__init__.py\", line 289, in wrapped_f\n",
            "    return self(f, *args, **kw)\n",
            "  File \"/usr/local/lib/python3.10/dist-packages/tenacity/__init__.py\", line 379, in __call__\n",
            "    do = self.iter(retry_state=retry_state)\n",
            "  File \"/usr/local/lib/python3.10/dist-packages/tenacity/__init__.py\", line 325, in iter\n",
            "    raise retry_exc.reraise()\n",
            "  File \"/usr/local/lib/python3.10/dist-packages/tenacity/__init__.py\", line 158, in reraise\n",
            "    raise self.last_attempt.result()\n",
            "  File \"/usr/lib/python3.10/concurrent/futures/_base.py\", line 451, in result\n",
            "    return self.__get_result()\n",
            "  File \"/usr/lib/python3.10/concurrent/futures/_base.py\", line 403, in __get_result\n",
            "    raise self._exception\n",
            "  File \"/usr/local/lib/python3.10/dist-packages/tenacity/__init__.py\", line 382, in __call__\n",
            "    result = fn(*args, **kwargs)\n",
            "  File \"/usr/local/lib/python3.10/dist-packages/langchain/embeddings/openai.py\", line 104, in _embed_with_retry\n",
            "    response = embeddings.client.create(**kwargs)\n",
            "  File \"/usr/local/lib/python3.10/dist-packages/openai/api_resources/embedding.py\", line 33, in create\n",
            "    response = super().create(*args, **kwargs)\n",
            "  File \"/usr/local/lib/python3.10/dist-packages/openai/api_resources/abstract/engine_api_resource.py\", line 153, in create\n",
            "    response, _, api_key = requestor.request(\n",
            "  File \"/usr/local/lib/python3.10/dist-packages/openai/api_requestor.py\", line 298, in request\n",
            "    resp, got_stream = self._interpret_response(result, stream)\n",
            "  File \"/usr/local/lib/python3.10/dist-packages/openai/api_requestor.py\", line 700, in _interpret_response\n",
            "    self._interpret_response_line(\n",
            "  File \"/usr/local/lib/python3.10/dist-packages/openai/api_requestor.py\", line 765, in _interpret_response_line\n",
            "    raise self.handle_error_response(\n",
            "openai.error.RateLimitError: You exceeded your current quota, please check your plan and billing details. For more information on this error, read the docs: https://platform.openai.com/docs/guides/error-codes/api-errors.\n",
            "Error fetching or processing , exception: Exactly one of file, filename and url must be specified.\n",
            "Error fetching or processing , exception: Exactly one of file, filename and url must be specified.\n",
            "Retrying langchain.embeddings.openai.embed_with_retry.<locals>._embed_with_retry in 4.0 seconds as it raised RateLimitError: You exceeded your current quota, please check your plan and billing details. For more information on this error, read the docs: https://platform.openai.com/docs/guides/error-codes/api-errors..\n",
            "Retrying langchain.embeddings.openai.embed_with_retry.<locals>._embed_with_retry in 4.0 seconds as it raised RateLimitError: You exceeded your current quota, please check your plan and billing details. For more information on this error, read the docs: https://platform.openai.com/docs/guides/error-codes/api-errors..\n",
            "Retrying langchain.embeddings.openai.embed_with_retry.<locals>._embed_with_retry in 4.0 seconds as it raised RateLimitError: You exceeded your current quota, please check your plan and billing details. For more information on this error, read the docs: https://platform.openai.com/docs/guides/error-codes/api-errors..\n",
            "Retrying langchain.embeddings.openai.embed_with_retry.<locals>._embed_with_retry in 8.0 seconds as it raised RateLimitError: You exceeded your current quota, please check your plan and billing details. For more information on this error, read the docs: https://platform.openai.com/docs/guides/error-codes/api-errors..\n",
            "Retrying langchain.embeddings.openai.embed_with_retry.<locals>._embed_with_retry in 10.0 seconds as it raised RateLimitError: You exceeded your current quota, please check your plan and billing details. For more information on this error, read the docs: https://platform.openai.com/docs/guides/error-codes/api-errors..\n",
            "2024-05-06 07:56:36.187 Uncaught app exception\n",
            "Traceback (most recent call last):\n",
            "  File \"/usr/local/lib/python3.10/dist-packages/streamlit/runtime/scriptrunner/script_runner.py\", line 565, in _run_script\n",
            "    exec(code, module.__dict__)\n",
            "  File \"/content/app.py\", line 46, in <module>\n",
            "    vectorstore_openai = FAISS.from_documents(docs, embeddings)\n",
            "  File \"/usr/local/lib/python3.10/dist-packages/langchain/vectorstores/base.py\", line 417, in from_documents\n",
            "    return cls.from_texts(texts, embedding, metadatas=metadatas, **kwargs)\n",
            "  File \"/usr/local/lib/python3.10/dist-packages/langchain/vectorstores/faiss.py\", line 602, in from_texts\n",
            "    embeddings = embedding.embed_documents(texts)\n",
            "  File \"/usr/local/lib/python3.10/dist-packages/langchain/embeddings/openai.py\", line 483, in embed_documents\n",
            "    return self._get_len_safe_embeddings(texts, engine=self.deployment)\n",
            "  File \"/usr/local/lib/python3.10/dist-packages/langchain/embeddings/openai.py\", line 367, in _get_len_safe_embeddings\n",
            "    response = embed_with_retry(\n",
            "  File \"/usr/local/lib/python3.10/dist-packages/langchain/embeddings/openai.py\", line 107, in embed_with_retry\n",
            "    return _embed_with_retry(**kwargs)\n",
            "  File \"/usr/local/lib/python3.10/dist-packages/tenacity/__init__.py\", line 289, in wrapped_f\n",
            "    return self(f, *args, **kw)\n",
            "  File \"/usr/local/lib/python3.10/dist-packages/tenacity/__init__.py\", line 379, in __call__\n",
            "    do = self.iter(retry_state=retry_state)\n",
            "  File \"/usr/local/lib/python3.10/dist-packages/tenacity/__init__.py\", line 325, in iter\n",
            "    raise retry_exc.reraise()\n",
            "  File \"/usr/local/lib/python3.10/dist-packages/tenacity/__init__.py\", line 158, in reraise\n",
            "    raise self.last_attempt.result()\n",
            "  File \"/usr/lib/python3.10/concurrent/futures/_base.py\", line 451, in result\n",
            "    return self.__get_result()\n",
            "  File \"/usr/lib/python3.10/concurrent/futures/_base.py\", line 403, in __get_result\n",
            "    raise self._exception\n",
            "  File \"/usr/local/lib/python3.10/dist-packages/tenacity/__init__.py\", line 382, in __call__\n",
            "    result = fn(*args, **kwargs)\n",
            "  File \"/usr/local/lib/python3.10/dist-packages/langchain/embeddings/openai.py\", line 104, in _embed_with_retry\n",
            "    response = embeddings.client.create(**kwargs)\n",
            "  File \"/usr/local/lib/python3.10/dist-packages/openai/api_resources/embedding.py\", line 33, in create\n",
            "    response = super().create(*args, **kwargs)\n",
            "  File \"/usr/local/lib/python3.10/dist-packages/openai/api_resources/abstract/engine_api_resource.py\", line 153, in create\n",
            "    response, _, api_key = requestor.request(\n",
            "  File \"/usr/local/lib/python3.10/dist-packages/openai/api_requestor.py\", line 298, in request\n",
            "    resp, got_stream = self._interpret_response(result, stream)\n",
            "  File \"/usr/local/lib/python3.10/dist-packages/openai/api_requestor.py\", line 700, in _interpret_response\n",
            "    self._interpret_response_line(\n",
            "  File \"/usr/local/lib/python3.10/dist-packages/openai/api_requestor.py\", line 765, in _interpret_response_line\n",
            "    raise self.handle_error_response(\n",
            "openai.error.RateLimitError: You exceeded your current quota, please check your plan and billing details. For more information on this error, read the docs: https://platform.openai.com/docs/guides/error-codes/api-errors.\n"
          ]
        }
      ]
    }
  ],
  "metadata": {
    "colab": {
      "provenance": [],
      "authorship_tag": "ABX9TyORzV/GrCqpbajIAEjcJ80E",
      "include_colab_link": true
    },
    "kernelspec": {
      "display_name": "Python 3",
      "name": "python3"
    },
    "language_info": {
      "name": "python"
    }
  },
  "nbformat": 4,
  "nbformat_minor": 0
}